<?xml version="1.0"?>
<robot  name="two_DOF_robot">

<!-- Used for fixing robot to Gazebo 'base_link' -->
  <link name="world"/>

  <joint name="glue_robot_to_world" type="fixed">
    <parent link="world"/>
    <child link="link0"/>
  </joint>

 <!-- Base Link -->
  <link name="link0">
    <visual>
      <origin xyz="0 0 0.5" rpy="0 0 0"/>
      <geometry>
        <box size="0.2 0.2 1"/>
      </geometry>
    </visual>
  </link>

<!-- The First Moveable Link -->
  <link name="link1">
    <visual>
      <origin xyz="0 0 0.5" rpy="0 0 0"/>
      <geometry>
        <cylinder length="1" radius="0.1"/>
      </geometry>
    </visual>
  </link>

<!-- The Second Moveable Link -->
  <link name="link2">
    <visual>
      <origin xyz="0 0 0.5" rpy="0 0 0"/>
      <geometry>
        <cylinder length="1" radius="0.1"/>
      </geometry>
    </visual>
  </link>

<!-- The First Joint Connecting Link0 and Link1 -->  
  <joint name="joint1" type="continuous">
    <parent link="link0"/>
    <child link="link1"/>
    <origin xyz="0 0 1" rpy="0 0 0"/>
    <axis xyz="0 1 0"/>
  </joint>

<!-- The First Joint Connecting Link1 and Link2 -->
  <joint name="joint2" type="continuous">
    <parent link="link1"/>
    <child link="link2"/>
    <origin xyz="0 0 1" rpy="0 0 0"/>
    <axis xyz="0 1 0"/>
  </joint>
</robot>

